[ 2025-06-11 22:27:13,411 ] 97 werkzeug - INFO - [31m[1mWARNING: This is a development server. Do not use it in a production deployment. Use a production WSGI server instead.[0m
 * Running on all addresses (0.0.0.0)
 * Running on http://127.0.0.1:5000
 * Running on http://192.168.18.63:5000
[ 2025-06-11 22:27:13,411 ] 97 werkzeug - INFO - [33mPress CTRL+C to quit[0m
[ 2025-06-11 22:27:43,609 ] 97 werkzeug - INFO - 127.0.0.1 - - [11/Jun/2025 22:27:43] "GET / HTTP/1.1" 200 -
[ 2025-06-11 22:27:44,612 ] 97 werkzeug - INFO - 127.0.0.1 - - [11/Jun/2025 22:27:44] "[33mGET /favicon.ico HTTP/1.1[0m" 404 -
[ 2025-06-11 22:27:50,916 ] 97 werkzeug - INFO - 127.0.0.1 - - [11/Jun/2025 22:27:50] "[33mGET /predict HTTP/1.1[0m" 404 -
[ 2025-06-11 22:28:01,147 ] 97 werkzeug - INFO - 127.0.0.1 - - [11/Jun/2025 22:28:01] "GET /predictdata HTTP/1.1" 200 -
[ 2025-06-11 22:28:57,831 ] 838 app - ERROR - Exception on /predictdata [POST]
Traceback (most recent call last):
  File "C:\Users\Zuhayr Adams\Projects\Project1\venv\lib\site-packages\flask\app.py", line 1473, in wsgi_app
    response = self.full_dispatch_request()
  File "C:\Users\Zuhayr Adams\Projects\Project1\venv\lib\site-packages\flask\app.py", line 882, in full_dispatch_request
    rv = self.handle_user_exception(e)
  File "C:\Users\Zuhayr Adams\Projects\Project1\venv\lib\site-packages\flask\app.py", line 880, in full_dispatch_request
    rv = self.dispatch_request()
  File "C:\Users\Zuhayr Adams\Projects\Project1\venv\lib\site-packages\flask\app.py", line 865, in dispatch_request
    return self.ensure_sync(self.view_functions[rule.endpoint])(**view_args)  # type: ignore[no-any-return]
  File "app.py", line 29, in predict_datapoint
    pred_df = data.get_data_as_dataframe()
AttributeError: 'CustomData' object has no attribute 'get_data_as_dataframe'
[ 2025-06-11 22:28:57,833 ] 97 werkzeug - INFO - 127.0.0.1 - - [11/Jun/2025 22:28:57] "[35m[1mPOST /predictdata HTTP/1.1[0m" 500 -
[ 2025-06-11 22:29:06,106 ] 97 werkzeug - INFO - 127.0.0.1 - - [11/Jun/2025 22:29:06] "GET /predictdata HTTP/1.1" 200 -
[ 2025-06-11 22:29:27,673 ] 838 app - ERROR - Exception on /predictdata [POST]
Traceback (most recent call last):
  File "C:\Users\Zuhayr Adams\Projects\Project1\venv\lib\site-packages\flask\app.py", line 1473, in wsgi_app
    response = self.full_dispatch_request()
  File "C:\Users\Zuhayr Adams\Projects\Project1\venv\lib\site-packages\flask\app.py", line 882, in full_dispatch_request
    rv = self.handle_user_exception(e)
  File "C:\Users\Zuhayr Adams\Projects\Project1\venv\lib\site-packages\flask\app.py", line 880, in full_dispatch_request
    rv = self.dispatch_request()
  File "C:\Users\Zuhayr Adams\Projects\Project1\venv\lib\site-packages\flask\app.py", line 865, in dispatch_request
    return self.ensure_sync(self.view_functions[rule.endpoint])(**view_args)  # type: ignore[no-any-return]
  File "app.py", line 29, in predict_datapoint
    pred_df = data.get_data_as_dataframe()
AttributeError: 'CustomData' object has no attribute 'get_data_as_dataframe'
[ 2025-06-11 22:29:27,673 ] 97 werkzeug - INFO - 127.0.0.1 - - [11/Jun/2025 22:29:27] "[35m[1mPOST /predictdata HTTP/1.1[0m" 500 -
